[2025-04-14T17:31:24.401+0000] {local_task_job_runner.py:123} INFO - ::group::Pre task execution logs
[2025-04-14T17:31:24.420+0000] {taskinstance.py:2614} INFO - Dependencies all met for dep_context=non-requeueable deps ti=<TaskInstance: batdongsan_scraping.save_links manual__2025-04-14T17:31:22.628767+00:00 [queued]>
[2025-04-14T17:31:24.430+0000] {taskinstance.py:2614} INFO - Dependencies all met for dep_context=requeueable deps ti=<TaskInstance: batdongsan_scraping.save_links manual__2025-04-14T17:31:22.628767+00:00 [queued]>
[2025-04-14T17:31:24.431+0000] {taskinstance.py:2867} INFO - Starting attempt 1 of 3
[2025-04-14T17:31:24.443+0000] {taskinstance.py:2890} INFO - Executing <Task(PythonOperator): save_links> on 2025-04-14 17:31:22.628767+00:00
[2025-04-14T17:31:24.455+0000] {standard_task_runner.py:104} INFO - Running: ['***', 'tasks', 'run', 'batdongsan_scraping', 'save_links', 'manual__2025-04-14T17:31:22.628767+00:00', '--job-id', '2', '--raw', '--subdir', 'DAGS_FOLDER/batdongsan_scraping_dag.py', '--cfg-path', '/tmp/tmpi3xnb7jh']
[2025-04-14T17:31:24.458+0000] {standard_task_runner.py:105} INFO - Job 2: Subtask save_links
[2025-04-14T17:31:24.460+0000] {logging_mixin.py:190} WARNING - /home/***/.local/lib/python3.12/site-packages/***/task/task_runner/standard_task_runner.py:70 DeprecationWarning: This process (pid=191) is multi-threaded, use of fork() may lead to deadlocks in the child.
[2025-04-14T17:31:24.462+0000] {standard_task_runner.py:72} INFO - Started process 193 to run task
[2025-04-14T17:31:24.504+0000] {task_command.py:467} INFO - Running <TaskInstance: batdongsan_scraping.save_links manual__2025-04-14T17:31:22.628767+00:00 [running]> on host 9b73e981a31f
[2025-04-14T17:31:24.584+0000] {taskinstance.py:3134} INFO - Exporting env vars: AIRFLOW_CTX_DAG_OWNER='***' AIRFLOW_CTX_DAG_ID='batdongsan_scraping' AIRFLOW_CTX_TASK_ID='save_links' AIRFLOW_CTX_EXECUTION_DATE='2025-04-14T17:31:22.628767+00:00' AIRFLOW_CTX_TRY_NUMBER='1' AIRFLOW_CTX_DAG_RUN_ID='manual__2025-04-14T17:31:22.628767+00:00'
[2025-04-14T17:31:24.585+0000] {taskinstance.py:732} INFO - ::endgroup::
[2025-04-14T17:31:24.677+0000] {SaveLinkBatdongsan.py:118} INFO - Loaded 60847 existing links
[2025-04-14T17:31:25.371+0000] {SaveLinkBatdongsan.py:135} INFO - Scraping page 3: https://batdongsan.com.vn/nha-dat-ban/p3?gtn=7-ty&gcn=30-ty
[2025-04-14T17:31:25.413+0000] {SaveLinkBatdongsan.py:135} INFO - Scraping page 1: https://batdongsan.com.vn/nha-dat-ban/p1?gtn=7-ty&gcn=30-ty
[2025-04-14T17:31:25.424+0000] {SaveLinkBatdongsan.py:135} INFO - Scraping page 4: https://batdongsan.com.vn/nha-dat-ban/p4?gtn=7-ty&gcn=30-ty
[2025-04-14T17:31:25.443+0000] {SaveLinkBatdongsan.py:135} INFO - Scraping page 5: https://batdongsan.com.vn/nha-dat-ban/p5?gtn=7-ty&gcn=30-ty
[2025-04-14T17:31:25.449+0000] {SaveLinkBatdongsan.py:135} INFO - Scraping page 2: https://batdongsan.com.vn/nha-dat-ban/p2?gtn=7-ty&gcn=30-ty
[2025-04-14T17:31:26.388+0000] {SaveLinkBatdongsan.py:141} INFO - Found 0 links on page 3
[2025-04-14T17:31:26.395+0000] {SaveLinkBatdongsan.py:147} WARNING - No links found on page 3, added to error file
[2025-04-14T17:31:27.622+0000] {SaveLinkBatdongsan.py:135} INFO - Scraping page 6: https://batdongsan.com.vn/nha-dat-ban/p6?gtn=7-ty&gcn=30-ty
[2025-04-14T17:31:34.765+0000] {SaveLinkBatdongsan.py:141} INFO - Found 20 links on page 1
[2025-04-14T17:31:36.174+0000] {SaveLinkBatdongsan.py:135} INFO - Scraping page 7: https://batdongsan.com.vn/nha-dat-ban/p7?gtn=7-ty&gcn=30-ty
[2025-04-14T17:31:36.768+0000] {SaveLinkBatdongsan.py:141} INFO - Found 20 links on page 2
[2025-04-14T17:31:36.945+0000] {SaveLinkBatdongsan.py:141} INFO - Found 20 links on page 4
[2025-04-14T17:31:37.570+0000] {SaveLinkBatdongsan.py:141} INFO - Found 20 links on page 5
[2025-04-14T17:31:38.398+0000] {SaveLinkBatdongsan.py:135} INFO - Scraping page 8: https://batdongsan.com.vn/nha-dat-ban/p8?gtn=7-ty&gcn=30-ty
[2025-04-14T17:31:38.406+0000] {SaveLinkBatdongsan.py:135} INFO - Scraping page 9: https://batdongsan.com.vn/nha-dat-ban/p9?gtn=7-ty&gcn=30-ty
[2025-04-14T17:31:38.539+0000] {SaveLinkBatdongsan.py:141} INFO - Found 20 links on page 6
[2025-04-14T17:31:39.407+0000] {SaveLinkBatdongsan.py:135} INFO - Scraping page 10: https://batdongsan.com.vn/nha-dat-ban/p10?gtn=7-ty&gcn=30-ty
[2025-04-14T17:31:39.606+0000] {SaveLinkBatdongsan.py:135} INFO - Scraping page 11: https://batdongsan.com.vn/nha-dat-ban/p11?gtn=7-ty&gcn=30-ty
[2025-04-14T17:31:47.820+0000] {SaveLinkBatdongsan.py:141} INFO - Found 20 links on page 7
[2025-04-14T17:31:48.880+0000] {SaveLinkBatdongsan.py:135} INFO - Scraping page 12: https://batdongsan.com.vn/nha-dat-ban/p12?gtn=7-ty&gcn=30-ty
[2025-04-14T17:31:51.353+0000] {SaveLinkBatdongsan.py:141} INFO - Found 20 links on page 9
[2025-04-14T17:31:51.405+0000] {SaveLinkBatdongsan.py:141} INFO - Found 20 links on page 8
[2025-04-14T17:31:52.724+0000] {SaveLinkBatdongsan.py:135} INFO - Scraping page 13: https://batdongsan.com.vn/nha-dat-ban/p13?gtn=7-ty&gcn=30-ty
[2025-04-14T17:31:52.822+0000] {SaveLinkBatdongsan.py:141} INFO - Found 20 links on page 11
[2025-04-14T17:31:52.993+0000] {SaveLinkBatdongsan.py:135} INFO - Scraping page 14: https://batdongsan.com.vn/nha-dat-ban/p14?gtn=7-ty&gcn=30-ty
[2025-04-14T17:31:53.010+0000] {SaveLinkBatdongsan.py:141} INFO - Found 20 links on page 10
[2025-04-14T17:31:54.110+0000] {SaveLinkBatdongsan.py:135} INFO - Scraping page 15: https://batdongsan.com.vn/nha-dat-ban/p15?gtn=7-ty&gcn=30-ty
[2025-04-14T17:31:54.154+0000] {SaveLinkBatdongsan.py:135} INFO - Scraping page 16: https://batdongsan.com.vn/nha-dat-ban/p16?gtn=7-ty&gcn=30-ty
[2025-04-14T17:31:54.644+0000] {SaveLinkBatdongsan.py:125} INFO - Saved 60847 links to /opt/***/data/batdongsan_links.txt
[2025-04-14T17:31:54.647+0000] {SaveLinkBatdongsan.py:195} INFO - Progress saved at 10/100 pages
[2025-04-14T17:32:03.242+0000] {SaveLinkBatdongsan.py:141} INFO - Found 20 links on page 12
[2025-04-14T17:32:04.760+0000] {SaveLinkBatdongsan.py:135} INFO - Scraping page 17: https://batdongsan.com.vn/nha-dat-ban/p17?gtn=7-ty&gcn=30-ty
[2025-04-14T17:32:11.191+0000] {SaveLinkBatdongsan.py:141} INFO - Found 20 links on page 14
[2025-04-14T17:32:11.522+0000] {SaveLinkBatdongsan.py:141} INFO - Found 20 links on page 16
[2025-04-14T17:32:11.687+0000] {SaveLinkBatdongsan.py:141} INFO - Found 20 links on page 13
[2025-04-14T17:32:11.739+0000] {SaveLinkBatdongsan.py:141} INFO - Found 20 links on page 15
[2025-04-14T17:32:13.049+0000] {SaveLinkBatdongsan.py:135} INFO - Scraping page 19: https://batdongsan.com.vn/nha-dat-ban/p19?gtn=7-ty&gcn=30-ty
[2025-04-14T17:32:13.180+0000] {SaveLinkBatdongsan.py:135} INFO - Scraping page 21: https://batdongsan.com.vn/nha-dat-ban/p21?gtn=7-ty&gcn=30-ty
[2025-04-14T17:32:13.197+0000] {SaveLinkBatdongsan.py:135} INFO - Scraping page 20: https://batdongsan.com.vn/nha-dat-ban/p20?gtn=7-ty&gcn=30-ty
[2025-04-14T17:32:13.213+0000] {SaveLinkBatdongsan.py:135} INFO - Scraping page 18: https://batdongsan.com.vn/nha-dat-ban/p18?gtn=7-ty&gcn=30-ty
[2025-04-14T17:32:14.488+0000] {SaveLinkBatdongsan.py:141} INFO - Found 0 links on page 19
[2025-04-14T17:32:14.513+0000] {SaveLinkBatdongsan.py:147} WARNING - No links found on page 19, added to error file
[2025-04-14T17:32:15.963+0000] {SaveLinkBatdongsan.py:135} INFO - Scraping page 22: https://batdongsan.com.vn/nha-dat-ban/p22?gtn=7-ty&gcn=30-ty
[2025-04-14T17:32:20.746+0000] {SaveLinkBatdongsan.py:141} INFO - Found 20 links on page 17
[2025-04-14T17:32:20.826+0000] {local_task_job_runner.py:346} WARNING - State of this instance has been externally set to None. Terminating instance.
[2025-04-14T17:32:20.837+0000] {local_task_job_runner.py:245} INFO - ::endgroup::
[2025-04-14T17:32:20.867+0000] {process_utils.py:132} INFO - Sending 15 to group 193. PIDs of all processes in the group: [3110, 3436, 3473, 3487, 4172, 4184, 4215, 4217, 4241, 4258, 4297, 4307, 4398, 4240, 3523, 3617, 3620, 3745, 3794, 3877, 3934, 4338, 3741, 3488, 3572, 3573, 3721, 3744, 3892, 3933, 4348, 3699, 3443, 3508, 3511, 3583, 3610, 3854, 3949, 4359, 3571, 193]
[2025-04-14T17:32:20.868+0000] {process_utils.py:87} INFO - Sending the signal 15 to group 193
[2025-04-14T17:32:20.873+0000] {taskinstance.py:3094} ERROR - Received SIGTERM. Terminating subprocesses.
[2025-04-14T17:32:20.896+0000] {SaveLinkBatdongsan.py:105} WARNING - Attempt 1 failed: ('Connection aborted.', RemoteDisconnected('Remote end closed connection without response'))
[2025-04-14T17:32:20.942+0000] {SaveLinkBatdongsan.py:105} WARNING - Attempt 1 failed: ('Connection aborted.', RemoteDisconnected('Remote end closed connection without response'))
[2025-04-14T17:32:20.943+0000] {SaveLinkBatdongsan.py:105} WARNING - Attempt 1 failed: ('Connection aborted.', RemoteDisconnected('Remote end closed connection without response'))
[2025-04-14T17:32:20.912+0000] {SaveLinkBatdongsan.py:105} WARNING - Attempt 1 failed: ('Connection aborted.', RemoteDisconnected('Remote end closed connection without response'))
[2025-04-14T17:32:20.982+0000] {taskinstance.py:3095} ERROR - Stacktrace: 
  File "/home/***/.local/bin/***", line 8, in <module>
    sys.exit(main())
  File "/home/***/.local/lib/python3.12/site-packages/***/__main__.py", line 62, in main
    args.func(args)
  File "/home/***/.local/lib/python3.12/site-packages/***/cli/cli_config.py", line 49, in command
    return func(*args, **kwargs)
  File "/home/***/.local/lib/python3.12/site-packages/***/utils/cli.py", line 116, in wrapper
    return f(*args, **kwargs)
  File "/home/***/.local/lib/python3.12/site-packages/***/utils/providers_configuration_loader.py", line 55, in wrapped_function
    return func(*args, **kwargs)
  File "/home/***/.local/lib/python3.12/site-packages/***/cli/commands/scheduler_command.py", line 56, in scheduler
    run_command_with_daemon_option(
  File "/home/***/.local/lib/python3.12/site-packages/***/cli/commands/daemon_utils.py", line 86, in run_command_with_daemon_option
    callback()
  File "/home/***/.local/lib/python3.12/site-packages/***/cli/commands/scheduler_command.py", line 59, in <lambda>
    callback=lambda: _run_scheduler_job(args),
  File "/home/***/.local/lib/python3.12/site-packages/***/cli/commands/scheduler_command.py", line 47, in _run_scheduler_job
    run_job(job=job_runner.job, execute_callable=job_runner._execute)
  File "/home/***/.local/lib/python3.12/site-packages/***/utils/session.py", line 97, in wrapper
    return func(*args, session=session, **kwargs)
  File "/home/***/.local/lib/python3.12/site-packages/***/jobs/job.py", line 421, in run_job
    return execute_job(job, execute_callable=execute_callable)
  File "/home/***/.local/lib/python3.12/site-packages/***/jobs/job.py", line 450, in execute_job
    ret = execute_callable()
  File "/home/***/.local/lib/python3.12/site-packages/***/jobs/scheduler_job_runner.py", line 990, in _execute
    executor.start()
  File "/home/***/.local/lib/python3.12/site-packages/***/executors/local_executor.py", line 392, in start
    self.impl.start()
  File "/home/***/.local/lib/python3.12/site-packages/***/executors/local_executor.py", line 330, in start
    worker.start()
  File "/usr/local/lib/python3.12/multiprocessing/process.py", line 121, in start
    self._popen = self._Popen(self)
  File "/usr/local/lib/python3.12/multiprocessing/context.py", line 224, in _Popen
    return _default_context.get_context().Process._Popen(process_obj)
  File "/usr/local/lib/python3.12/multiprocessing/context.py", line 282, in _Popen
    return Popen(process_obj)
  File "/usr/local/lib/python3.12/multiprocessing/popen_fork.py", line 19, in __init__
    self._launch(process_obj)
  File "/usr/local/lib/python3.12/multiprocessing/popen_fork.py", line 71, in _launch
    code = process_obj._bootstrap(parent_sentinel=child_r)
  File "/usr/local/lib/python3.12/multiprocessing/process.py", line 314, in _bootstrap
    self.run()
  File "/home/***/.local/lib/python3.12/site-packages/***/executors/local_executor.py", line 80, in run
    return super().run()
  File "/usr/local/lib/python3.12/multiprocessing/process.py", line 108, in run
    self._target(*self._args, **self._kwargs)
  File "/home/***/.local/lib/python3.12/site-packages/***/traces/tracer.py", line 58, in wrapper
    return func(*args, **kwargs)
  File "/home/***/.local/lib/python3.12/site-packages/***/executors/local_executor.py", line 211, in do_work
    self.execute_work(key=key, command=command)
  File "/home/***/.local/lib/python3.12/site-packages/***/traces/tracer.py", line 58, in wrapper
    return func(*args, **kwargs)
  File "/home/***/.local/lib/python3.12/site-packages/***/executors/local_executor.py", line 100, in execute_work
    state = self._execute_work_in_fork(command)
  File "/home/***/.local/lib/python3.12/site-packages/***/traces/tracer.py", line 58, in wrapper
    return func(*args, **kwargs)
  File "/home/***/.local/lib/python3.12/site-packages/***/executors/local_executor.py", line 142, in _execute_work_in_fork
    args.func(args)
  File "/home/***/.local/lib/python3.12/site-packages/***/cli/cli_config.py", line 49, in command
    return func(*args, **kwargs)
  File "/home/***/.local/lib/python3.12/site-packages/***/utils/cli.py", line 116, in wrapper
    return f(*args, **kwargs)
  File "/home/***/.local/lib/python3.12/site-packages/***/cli/commands/task_command.py", line 483, in task_run
    task_return_code = _run_task_by_selected_method(args, _dag, ti)
  File "/home/***/.local/lib/python3.12/site-packages/***/cli/commands/task_command.py", line 254, in _run_task_by_selected_method
    return _run_task_by_local_task_job(args, ti)
  File "/home/***/.local/lib/python3.12/site-packages/***/cli/commands/task_command.py", line 322, in _run_task_by_local_task_job
    ret = run_job(job=job_runner.job, execute_callable=job_runner._execute)
  File "/home/***/.local/lib/python3.12/site-packages/***/utils/session.py", line 97, in wrapper
    return func(*args, session=session, **kwargs)
  File "/home/***/.local/lib/python3.12/site-packages/***/jobs/job.py", line 421, in run_job
    return execute_job(job, execute_callable=execute_callable)
  File "/home/***/.local/lib/python3.12/site-packages/***/jobs/job.py", line 450, in execute_job
    ret = execute_callable()
  File "/home/***/.local/lib/python3.12/site-packages/***/jobs/local_task_job_runner.py", line 171, in _execute
    self.task_runner.start()
  File "/home/***/.local/lib/python3.12/site-packages/***/task/task_runner/standard_task_runner.py", line 55, in start
    self.process = self._start_by_fork()
  File "/home/***/.local/lib/python3.12/site-packages/***/task/task_runner/standard_task_runner.py", line 117, in _start_by_fork
    ret = args.func(args, dag=self.dag)
  File "/home/***/.local/lib/python3.12/site-packages/***/cli/cli_config.py", line 49, in command
    return func(*args, **kwargs)
  File "/home/***/.local/lib/python3.12/site-packages/***/utils/cli.py", line 116, in wrapper
    return f(*args, **kwargs)
  File "/home/***/.local/lib/python3.12/site-packages/***/cli/commands/task_command.py", line 483, in task_run
    task_return_code = _run_task_by_selected_method(args, _dag, ti)
  File "/home/***/.local/lib/python3.12/site-packages/***/cli/commands/task_command.py", line 256, in _run_task_by_selected_method
    return _run_raw_task(args, ti)
  File "/home/***/.local/lib/python3.12/site-packages/***/cli/commands/task_command.py", line 341, in _run_raw_task
    return ti._run_raw_task(
  File "/home/***/.local/lib/python3.12/site-packages/***/utils/session.py", line 97, in wrapper
    return func(*args, session=session, **kwargs)
  File "/home/***/.local/lib/python3.12/site-packages/***/models/taskinstance.py", line 3006, in _run_raw_task
    return _run_raw_task(
  File "/home/***/.local/lib/python3.12/site-packages/***/models/taskinstance.py", line 274, in _run_raw_task
    TaskInstance._execute_task_with_callbacks(
  File "/home/***/.local/lib/python3.12/site-packages/***/models/taskinstance.py", line 3161, in _execute_task_with_callbacks
    result = self._execute_task(context, task_orig)
  File "/home/***/.local/lib/python3.12/site-packages/***/models/taskinstance.py", line 3185, in _execute_task
    return _execute_task(self, context, task_orig)
  File "/home/***/.local/lib/python3.12/site-packages/***/models/taskinstance.py", line 768, in _execute_task
    result = _execute_callable(context=context, **execute_callable_kwargs)
  File "/home/***/.local/lib/python3.12/site-packages/***/models/taskinstance.py", line 734, in _execute_callable
    return ExecutionCallableRunner(
  File "/home/***/.local/lib/python3.12/site-packages/***/utils/operator_helpers.py", line 252, in run
    return self.func(*args, **kwargs)
  File "/home/***/.local/lib/python3.12/site-packages/***/models/baseoperator.py", line 424, in wrapper
    return func(self, *args, **kwargs)
  File "/home/***/.local/lib/python3.12/site-packages/***/operators/python.py", line 238, in execute
    return_value = self.execute_callable()
  File "/home/***/.local/lib/python3.12/site-packages/***/operators/python.py", line 256, in execute_callable
    return runner.run(*self.op_args, **self.op_kwargs)
  File "/home/***/.local/lib/python3.12/site-packages/***/utils/operator_helpers.py", line 252, in run
    return self.func(*args, **kwargs)
  File "/opt/***/dags/batdongsan_scraping_dag.py", line 50, in save_links_task
    scraper.run()
  File "/opt/***/dags/../scripts/SaveLinkBatdongsan.py", line 290, in run
    self.scrape_all_pages()
  File "/opt/***/dags/../scripts/SaveLinkBatdongsan.py", line 186, in scrape_all_pages
    for future in concurrent.futures.as_completed(futures):
  File "/usr/local/lib/python3.12/concurrent/futures/_base.py", line 243, in as_completed
    waiter.event.wait(wait_timeout)
  File "/usr/local/lib/python3.12/threading.py", line 655, in wait
    signaled = self._cond.wait(timeout)
  File "/usr/local/lib/python3.12/threading.py", line 355, in wait
    waiter.acquire()
  File "/home/***/.local/lib/python3.12/site-packages/***/models/taskinstance.py", line 3095, in signal_handler
    self.log.error("Stacktrace: \n%s", "".join(traceback.format_stack()))

[2025-04-14T17:32:21.003+0000] {process_utils.py:80} INFO - Process psutil.Process(pid=3488, status='terminated', started='17:32:11') (3488) terminated with exit code None
[2025-04-14T17:32:21.015+0000] {process_utils.py:80} INFO - Process psutil.Process(pid=3523, status='terminated', started='17:32:11') (3523) terminated with exit code None
[2025-04-14T17:32:21.018+0000] {process_utils.py:80} INFO - Process psutil.Process(pid=3610, status='terminated', started='17:32:11') (3610) terminated with exit code None
[2025-04-14T17:32:21.020+0000] {process_utils.py:80} INFO - Process psutil.Process(pid=4297, status='terminated', started='17:32:15') (4297) terminated with exit code None
[2025-04-14T17:32:21.032+0000] {process_utils.py:80} INFO - Process psutil.Process(pid=3744, status='terminated', started='17:32:11') (3744) terminated with exit code None
[2025-04-14T17:32:21.066+0000] {process_utils.py:80} INFO - Process psutil.Process(pid=4217, status='terminated', started='17:32:14') (4217) terminated with exit code None
[2025-04-14T17:32:21.068+0000] {process_utils.py:80} INFO - Process psutil.Process(pid=4240, status='terminated', started='17:32:14') (4240) terminated with exit code None
[2025-04-14T17:32:21.071+0000] {process_utils.py:80} INFO - Process psutil.Process(pid=4359, status='terminated', started='17:32:17') (4359) terminated with exit code None
[2025-04-14T17:32:21.073+0000] {process_utils.py:80} INFO - Process psutil.Process(pid=3573, status='terminated', started='17:32:11') (3573) terminated with exit code None
[2025-04-14T17:32:21.075+0000] {process_utils.py:80} INFO - Process psutil.Process(pid=3571, status='terminated', started='17:32:11') (3571) terminated with exit code None
[2025-04-14T17:32:21.076+0000] {process_utils.py:80} INFO - Process psutil.Process(pid=4241, status='terminated', started='17:32:14') (4241) terminated with exit code None
[2025-04-14T17:32:21.079+0000] {process_utils.py:80} INFO - Process psutil.Process(pid=3583, status='terminated', started='17:32:11') (3583) terminated with exit code None
[2025-04-14T17:32:21.082+0000] {process_utils.py:80} INFO - Process psutil.Process(pid=3854, status='terminated', started='17:32:12') (3854) terminated with exit code None
[2025-04-14T17:32:21.083+0000] {process_utils.py:80} INFO - Process psutil.Process(pid=4307, status='terminated', started='17:32:15') (4307) terminated with exit code None
[2025-04-14T17:32:21.084+0000] {process_utils.py:80} INFO - Process psutil.Process(pid=3443, status='terminated', started='17:32:11') (3443) terminated with exit code None
[2025-04-14T17:32:21.085+0000] {process_utils.py:80} INFO - Process psutil.Process(pid=3794, status='terminated', started='17:32:11') (3794) terminated with exit code None
[2025-04-14T17:32:21.086+0000] {process_utils.py:80} INFO - Process psutil.Process(pid=3741, status='terminated', started='17:32:11') (3741) terminated with exit code None
[2025-04-14T17:32:21.091+0000] {process_utils.py:80} INFO - Process psutil.Process(pid=3511, status='terminated', started='17:32:11') (3511) terminated with exit code None
[2025-04-14T17:32:21.094+0000] {process_utils.py:80} INFO - Process psutil.Process(pid=3620, status='terminated', started='17:32:11') (3620) terminated with exit code None
[2025-04-14T17:32:21.131+0000] {process_utils.py:80} INFO - Process psutil.Process(pid=4398, status='terminated', started='17:32:19') (4398) terminated with exit code None
[2025-04-14T17:32:21.132+0000] {process_utils.py:80} INFO - Process psutil.Process(pid=3934, status='terminated', started='17:32:12') (3934) terminated with exit code None
[2025-04-14T17:32:21.133+0000] {process_utils.py:80} INFO - Process psutil.Process(pid=4338, status='terminated', started='17:32:16') (4338) terminated with exit code None
[2025-04-14T17:32:21.134+0000] {process_utils.py:80} INFO - Process psutil.Process(pid=3892, status='terminated', started='17:32:12') (3892) terminated with exit code None
[2025-04-14T17:32:21.136+0000] {process_utils.py:80} INFO - Process psutil.Process(pid=3721, status='terminated', started='17:32:11') (3721) terminated with exit code None
[2025-04-14T17:32:21.138+0000] {process_utils.py:80} INFO - Process psutil.Process(pid=3949, status='terminated', started='17:32:12') (3949) terminated with exit code None
[2025-04-14T17:32:21.173+0000] {process_utils.py:80} INFO - Process psutil.Process(pid=4215, status='terminated', started='17:32:14') (4215) terminated with exit code None
[2025-04-14T17:32:21.178+0000] {process_utils.py:80} INFO - Process psutil.Process(pid=4258, status='terminated', started='17:32:14') (4258) terminated with exit code None
[2025-04-14T17:32:21.181+0000] {process_utils.py:80} INFO - Process psutil.Process(pid=3745, status='terminated', started='17:32:11') (3745) terminated with exit code None
[2025-04-14T17:32:21.183+0000] {process_utils.py:80} INFO - Process psutil.Process(pid=3699, status='terminated', started='17:32:11') (3699) terminated with exit code None
[2025-04-14T17:32:21.188+0000] {process_utils.py:80} INFO - Process psutil.Process(pid=4184, status='terminated', started='17:32:14') (4184) terminated with exit code None
[2025-04-14T17:32:21.253+0000] {process_utils.py:80} INFO - Process psutil.Process(pid=4348, status='terminated', started='17:32:17') (4348) terminated with exit code None
[2025-04-14T17:32:21.254+0000] {process_utils.py:80} INFO - Process psutil.Process(pid=3572, status='terminated', started='17:32:11') (3572) terminated with exit code None
[2025-04-14T17:32:21.254+0000] {process_utils.py:80} INFO - Process psutil.Process(pid=3877, status='terminated', started='17:32:12') (3877) terminated with exit code None
[2025-04-14T17:32:21.258+0000] {process_utils.py:80} INFO - Process psutil.Process(pid=3933, status='terminated', started='17:32:12') (3933) terminated with exit code None
[2025-04-14T17:32:21.409+0000] {process_utils.py:80} INFO - Process psutil.Process(pid=3508, status='terminated', started='17:32:11') (3508) terminated with exit code None
[2025-04-14T17:32:21.580+0000] {SaveLinkBatdongsan.py:135} INFO - Scraping page 23: https://batdongsan.com.vn/nha-dat-ban/p23?gtn=7-ty&gcn=30-ty
[2025-04-14T17:32:21.696+0000] {process_utils.py:80} INFO - Process psutil.Process(pid=3617, status='terminated', started='17:32:11') (3617) terminated with exit code None
[2025-04-14T17:32:30.945+0000] {connectionpool.py:868} WARNING - Retrying (Retry(total=2, connect=None, read=None, redirect=None, status=None)) after connection broken by 'NewConnectionError('<urllib3.connection.HTTPConnection object at 0x7f0ec102a1b0>: Failed to establish a new connection: [Errno 111] Connection refused')': /session/59da8b5137dfb5cadb68e7bf848e8314/url
[2025-04-14T17:32:30.957+0000] {connectionpool.py:868} WARNING - Retrying (Retry(total=1, connect=None, read=None, redirect=None, status=None)) after connection broken by 'NewConnectionError('<urllib3.connection.HTTPConnection object at 0x7f0ec102a330>: Failed to establish a new connection: [Errno 111] Connection refused')': /session/59da8b5137dfb5cadb68e7bf848e8314/url
[2025-04-14T17:32:30.964+0000] {connectionpool.py:868} WARNING - Retrying (Retry(total=0, connect=None, read=None, redirect=None, status=None)) after connection broken by 'NewConnectionError('<urllib3.connection.HTTPConnection object at 0x7f0ec102acf0>: Failed to establish a new connection: [Errno 111] Connection refused')': /session/59da8b5137dfb5cadb68e7bf848e8314/url
[2025-04-14T17:32:30.972+0000] {SaveLinkBatdongsan.py:105} WARNING - Attempt 2 failed: HTTPConnectionPool(host='localhost', port=57597): Max retries exceeded with url: /session/59da8b5137dfb5cadb68e7bf848e8314/url (Caused by NewConnectionError('<urllib3.connection.HTTPConnection object at 0x7f0ec102afc0>: Failed to establish a new connection: [Errno 111] Connection refused'))
[2025-04-14T17:32:30.961+0000] {connectionpool.py:868} WARNING - Retrying (Retry(total=2, connect=None, read=None, redirect=None, status=None)) after connection broken by 'NewConnectionError('<urllib3.connection.HTTPConnection object at 0x7f0ec102a810>: Failed to establish a new connection: [Errno 111] Connection refused')': /session/2c4871bc7066ce27dc562f81652666e7/url
[2025-04-14T17:32:30.966+0000] {connectionpool.py:868} WARNING - Retrying (Retry(total=2, connect=None, read=None, redirect=None, status=None)) after connection broken by 'NewConnectionError('<urllib3.connection.HTTPConnection object at 0x7f0ec102ab70>: Failed to establish a new connection: [Errno 111] Connection refused')': /session/d4792fc020ce44acf03cb058b0ac3794/url
[2025-04-14T17:32:30.988+0000] {connectionpool.py:868} WARNING - Retrying (Retry(total=1, connect=None, read=None, redirect=None, status=None)) after connection broken by 'NewConnectionError('<urllib3.connection.HTTPConnection object at 0x7f0ec1029fa0>: Failed to establish a new connection: [Errno 111] Connection refused')': /session/2c4871bc7066ce27dc562f81652666e7/url
[2025-04-14T17:32:31.010+0000] {connectionpool.py:868} WARNING - Retrying (Retry(total=0, connect=None, read=None, redirect=None, status=None)) after connection broken by 'NewConnectionError('<urllib3.connection.HTTPConnection object at 0x7f0ec102b980>: Failed to establish a new connection: [Errno 111] Connection refused')': /session/2c4871bc7066ce27dc562f81652666e7/url
[2025-04-14T17:32:31.027+0000] {SaveLinkBatdongsan.py:105} WARNING - Attempt 2 failed: HTTPConnectionPool(host='localhost', port=60457): Max retries exceeded with url: /session/2c4871bc7066ce27dc562f81652666e7/url (Caused by NewConnectionError('<urllib3.connection.HTTPConnection object at 0x7f0ec102bb60>: Failed to establish a new connection: [Errno 111] Connection refused'))
[2025-04-14T17:32:31.009+0000] {connectionpool.py:868} WARNING - Retrying (Retry(total=1, connect=None, read=None, redirect=None, status=None)) after connection broken by 'NewConnectionError('<urllib3.connection.HTTPConnection object at 0x7f0ec102b500>: Failed to establish a new connection: [Errno 111] Connection refused')': /session/d4792fc020ce44acf03cb058b0ac3794/url
[2025-04-14T17:32:31.010+0000] {connectionpool.py:868} WARNING - Retrying (Retry(total=2, connect=None, read=None, redirect=None, status=None)) after connection broken by 'NewConnectionError('<urllib3.connection.HTTPConnection object at 0x7f0ec102b6e0>: Failed to establish a new connection: [Errno 111] Connection refused')': /session/a15a413670dbd32d691b439dee588d77/url
[2025-04-14T17:32:31.058+0000] {connectionpool.py:868} WARNING - Retrying (Retry(total=1, connect=None, read=None, redirect=None, status=None)) after connection broken by 'NewConnectionError('<urllib3.connection.HTTPConnection object at 0x7f0ec11c3800>: Failed to establish a new connection: [Errno 111] Connection refused')': /session/a15a413670dbd32d691b439dee588d77/url
[2025-04-14T17:32:31.055+0000] {connectionpool.py:868} WARNING - Retrying (Retry(total=0, connect=None, read=None, redirect=None, status=None)) after connection broken by 'NewConnectionError('<urllib3.connection.HTTPConnection object at 0x7f0ec0f249b0>: Failed to establish a new connection: [Errno 111] Connection refused')': /session/d4792fc020ce44acf03cb058b0ac3794/url
[2025-04-14T17:32:31.071+0000] {connectionpool.py:868} WARNING - Retrying (Retry(total=0, connect=None, read=None, redirect=None, status=None)) after connection broken by 'NewConnectionError('<urllib3.connection.HTTPConnection object at 0x7f0ec102bd40>: Failed to establish a new connection: [Errno 111] Connection refused')': /session/a15a413670dbd32d691b439dee588d77/url
[2025-04-14T17:32:31.087+0000] {SaveLinkBatdongsan.py:105} WARNING - Attempt 2 failed: HTTPConnectionPool(host='localhost', port=49823): Max retries exceeded with url: /session/a15a413670dbd32d691b439dee588d77/url (Caused by NewConnectionError('<urllib3.connection.HTTPConnection object at 0x7f0ec10e4380>: Failed to establish a new connection: [Errno 111] Connection refused'))
[2025-04-14T17:32:31.088+0000] {SaveLinkBatdongsan.py:105} WARNING - Attempt 2 failed: HTTPConnectionPool(host='localhost', port=42983): Max retries exceeded with url: /session/d4792fc020ce44acf03cb058b0ac3794/url (Caused by NewConnectionError('<urllib3.connection.HTTPConnection object at 0x7f0ec10e4230>: Failed to establish a new connection: [Errno 111] Connection refused'))
[2025-04-14T17:32:34.117+0000] {SaveLinkBatdongsan.py:141} INFO - Found 20 links on page 23
[2025-04-14T17:32:35.462+0000] {SaveLinkBatdongsan.py:135} INFO - Scraping page 24: https://batdongsan.com.vn/nha-dat-ban/p24?gtn=7-ty&gcn=30-ty
[2025-04-14T17:32:40.990+0000] {connectionpool.py:868} WARNING - Retrying (Retry(total=2, connect=None, read=None, redirect=None, status=None)) after connection broken by 'NewConnectionError('<urllib3.connection.HTTPConnection object at 0x7f0ec06ca5d0>: Failed to establish a new connection: [Errno 111] Connection refused')': /session/59da8b5137dfb5cadb68e7bf848e8314/url
[2025-04-14T17:32:40.996+0000] {connectionpool.py:868} WARNING - Retrying (Retry(total=1, connect=None, read=None, redirect=None, status=None)) after connection broken by 'NewConnectionError('<urllib3.connection.HTTPConnection object at 0x7f0ec06ca990>: Failed to establish a new connection: [Errno 111] Connection refused')': /session/59da8b5137dfb5cadb68e7bf848e8314/url
[2025-04-14T17:32:41.018+0000] {connectionpool.py:868} WARNING - Retrying (Retry(total=0, connect=None, read=None, redirect=None, status=None)) after connection broken by 'NewConnectionError('<urllib3.connection.HTTPConnection object at 0x7f0ec06caba0>: Failed to establish a new connection: [Errno 111] Connection refused')': /session/59da8b5137dfb5cadb68e7bf848e8314/url
[2025-04-14T17:32:41.032+0000] {SaveLinkBatdongsan.py:105} WARNING - Attempt 3 failed: HTTPConnectionPool(host='localhost', port=57597): Max retries exceeded with url: /session/59da8b5137dfb5cadb68e7bf848e8314/url (Caused by NewConnectionError('<urllib3.connection.HTTPConnection object at 0x7f0ec06caea0>: Failed to establish a new connection: [Errno 111] Connection refused'))
[2025-04-14T17:32:41.045+0000] {connectionpool.py:868} WARNING - Retrying (Retry(total=2, connect=None, read=None, redirect=None, status=None)) after connection broken by 'NewConnectionError('<urllib3.connection.HTTPConnection object at 0x7f0ec06cb3b0>: Failed to establish a new connection: [Errno 111] Connection refused')': /session/2c4871bc7066ce27dc562f81652666e7/url
[2025-04-14T17:32:41.064+0000] {connectionpool.py:868} WARNING - Retrying (Retry(total=1, connect=None, read=None, redirect=None, status=None)) after connection broken by 'NewConnectionError('<urllib3.connection.HTTPConnection object at 0x7f0ec06cb500>: Failed to establish a new connection: [Errno 111] Connection refused')': /session/2c4871bc7066ce27dc562f81652666e7/url
[2025-04-14T17:32:41.073+0000] {connectionpool.py:868} WARNING - Retrying (Retry(total=0, connect=None, read=None, redirect=None, status=None)) after connection broken by 'NewConnectionError('<urllib3.connection.HTTPConnection object at 0x7f0ec06cb890>: Failed to establish a new connection: [Errno 111] Connection refused')': /session/2c4871bc7066ce27dc562f81652666e7/url
[2025-04-14T17:32:41.083+0000] {SaveLinkBatdongsan.py:105} WARNING - Attempt 3 failed: HTTPConnectionPool(host='localhost', port=60457): Max retries exceeded with url: /session/2c4871bc7066ce27dc562f81652666e7/url (Caused by NewConnectionError('<urllib3.connection.HTTPConnection object at 0x7f0ec06cba70>: Failed to establish a new connection: [Errno 111] Connection refused'))
[2025-04-14T17:32:41.099+0000] {connectionpool.py:868} WARNING - Retrying (Retry(total=2, connect=None, read=None, redirect=None, status=None)) after connection broken by 'NewConnectionError('<urllib3.connection.HTTPConnection object at 0x7f0ec06e8230>: Failed to establish a new connection: [Errno 111] Connection refused')': /session/d4792fc020ce44acf03cb058b0ac3794/url
[2025-04-14T17:32:41.103+0000] {connectionpool.py:868} WARNING - Retrying (Retry(total=2, connect=None, read=None, redirect=None, status=None)) after connection broken by 'NewConnectionError('<urllib3.connection.HTTPConnection object at 0x7f0ec06cbfb0>: Failed to establish a new connection: [Errno 111] Connection refused')': /session/a15a413670dbd32d691b439dee588d77/url
[2025-04-14T17:32:41.110+0000] {connectionpool.py:868} WARNING - Retrying (Retry(total=1, connect=None, read=None, redirect=None, status=None)) after connection broken by 'NewConnectionError('<urllib3.connection.HTTPConnection object at 0x7f0ec06e8680>: Failed to establish a new connection: [Errno 111] Connection refused')': /session/a15a413670dbd32d691b439dee588d77/url
[2025-04-14T17:32:41.121+0000] {connectionpool.py:868} WARNING - Retrying (Retry(total=1, connect=None, read=None, redirect=None, status=None)) after connection broken by 'NewConnectionError('<urllib3.connection.HTTPConnection object at 0x7f0ec06e85f0>: Failed to establish a new connection: [Errno 111] Connection refused')': /session/d4792fc020ce44acf03cb058b0ac3794/url
[2025-04-14T17:32:41.133+0000] {connectionpool.py:868} WARNING - Retrying (Retry(total=0, connect=None, read=None, redirect=None, status=None)) after connection broken by 'NewConnectionError('<urllib3.connection.HTTPConnection object at 0x7f0ec06e8f80>: Failed to establish a new connection: [Errno 111] Connection refused')': /session/d4792fc020ce44acf03cb058b0ac3794/url
[2025-04-14T17:32:41.129+0000] {connectionpool.py:868} WARNING - Retrying (Retry(total=0, connect=None, read=None, redirect=None, status=None)) after connection broken by 'NewConnectionError('<urllib3.connection.HTTPConnection object at 0x7f0ec06e8b90>: Failed to establish a new connection: [Errno 111] Connection refused')': /session/a15a413670dbd32d691b439dee588d77/url
[2025-04-14T17:32:41.141+0000] {SaveLinkBatdongsan.py:105} WARNING - Attempt 3 failed: HTTPConnectionPool(host='localhost', port=49823): Max retries exceeded with url: /session/a15a413670dbd32d691b439dee588d77/url (Caused by NewConnectionError('<urllib3.connection.HTTPConnection object at 0x7f0ec06e9580>: Failed to establish a new connection: [Errno 111] Connection refused'))
[2025-04-14T17:32:41.138+0000] {SaveLinkBatdongsan.py:105} WARNING - Attempt 3 failed: HTTPConnectionPool(host='localhost', port=42983): Max retries exceeded with url: /session/d4792fc020ce44acf03cb058b0ac3794/url (Caused by NewConnectionError('<urllib3.connection.HTTPConnection object at 0x7f0ec06e9340>: Failed to establish a new connection: [Errno 111] Connection refused'))
[2025-04-14T17:32:50.369+0000] {SaveLinkBatdongsan.py:141} INFO - Found 20 links on page 24
[2025-04-14T17:32:51.061+0000] {connectionpool.py:868} WARNING - Retrying (Retry(total=2, connect=None, read=None, redirect=None, status=None)) after connection broken by 'NewConnectionError('<urllib3.connection.HTTPConnection object at 0x7f0ec00dcc80>: Failed to establish a new connection: [Errno 111] Connection refused')': /session/59da8b5137dfb5cadb68e7bf848e8314/url
[2025-04-14T17:32:51.069+0000] {connectionpool.py:868} WARNING - Retrying (Retry(total=1, connect=None, read=None, redirect=None, status=None)) after connection broken by 'NewConnectionError('<urllib3.connection.HTTPConnection object at 0x7f0ec00dce30>: Failed to establish a new connection: [Errno 111] Connection refused')': /session/59da8b5137dfb5cadb68e7bf848e8314/url
[2025-04-14T17:32:51.075+0000] {connectionpool.py:868} WARNING - Retrying (Retry(total=0, connect=None, read=None, redirect=None, status=None)) after connection broken by 'NewConnectionError('<urllib3.connection.HTTPConnection object at 0x7f0ec00dd040>: Failed to establish a new connection: [Errno 111] Connection refused')': /session/59da8b5137dfb5cadb68e7bf848e8314/url
[2025-04-14T17:32:51.081+0000] {SaveLinkBatdongsan.py:105} WARNING - Attempt 4 failed: HTTPConnectionPool(host='localhost', port=57597): Max retries exceeded with url: /session/59da8b5137dfb5cadb68e7bf848e8314/url (Caused by NewConnectionError('<urllib3.connection.HTTPConnection object at 0x7f0ec00dd520>: Failed to establish a new connection: [Errno 111] Connection refused'))
[2025-04-14T17:32:51.104+0000] {connectionpool.py:868} WARNING - Retrying (Retry(total=2, connect=None, read=None, redirect=None, status=None)) after connection broken by 'NewConnectionError('<urllib3.connection.HTTPConnection object at 0x7f0ec00dd9d0>: Failed to establish a new connection: [Errno 111] Connection refused')': /session/2c4871bc7066ce27dc562f81652666e7/url
[2025-04-14T17:32:51.112+0000] {connectionpool.py:868} WARNING - Retrying (Retry(total=1, connect=None, read=None, redirect=None, status=None)) after connection broken by 'NewConnectionError('<urllib3.connection.HTTPConnection object at 0x7f0ec00dd0d0>: Failed to establish a new connection: [Errno 111] Connection refused')': /session/2c4871bc7066ce27dc562f81652666e7/url
[2025-04-14T17:32:51.113+0000] {connectionpool.py:868} WARNING - Retrying (Retry(total=0, connect=None, read=None, redirect=None, status=None)) after connection broken by 'NewConnectionError('<urllib3.connection.HTTPConnection object at 0x7f0ec00dde80>: Failed to establish a new connection: [Errno 111] Connection refused')': /session/2c4871bc7066ce27dc562f81652666e7/url
[2025-04-14T17:32:51.119+0000] {SaveLinkBatdongsan.py:105} WARNING - Attempt 4 failed: HTTPConnectionPool(host='localhost', port=60457): Max retries exceeded with url: /session/2c4871bc7066ce27dc562f81652666e7/url (Caused by NewConnectionError('<urllib3.connection.HTTPConnection object at 0x7f0ec00de0c0>: Failed to establish a new connection: [Errno 111] Connection refused'))
[2025-04-14T17:32:51.191+0000] {connectionpool.py:868} WARNING - Retrying (Retry(total=2, connect=None, read=None, redirect=None, status=None)) after connection broken by 'NewConnectionError('<urllib3.connection.HTTPConnection object at 0x7f0ec00de7e0>: Failed to establish a new connection: [Errno 111] Connection refused')': /session/d4792fc020ce44acf03cb058b0ac3794/url
[2025-04-14T17:32:51.168+0000] {connectionpool.py:868} WARNING - Retrying (Retry(total=2, connect=None, read=None, redirect=None, status=None)) after connection broken by 'NewConnectionError('<urllib3.connection.HTTPConnection object at 0x7f0ec00de540>: Failed to establish a new connection: [Errno 111] Connection refused')': /session/a15a413670dbd32d691b439dee588d77/url
[2025-04-14T17:32:51.199+0000] {connectionpool.py:868} WARNING - Retrying (Retry(total=1, connect=None, read=None, redirect=None, status=None)) after connection broken by 'NewConnectionError('<urllib3.connection.HTTPConnection object at 0x7f0ec00de9c0>: Failed to establish a new connection: [Errno 111] Connection refused')': /session/d4792fc020ce44acf03cb058b0ac3794/url
[2025-04-14T17:32:51.206+0000] {connectionpool.py:868} WARNING - Retrying (Retry(total=1, connect=None, read=None, redirect=None, status=None)) after connection broken by 'NewConnectionError('<urllib3.connection.HTTPConnection object at 0x7f0ec00decf0>: Failed to establish a new connection: [Errno 111] Connection refused')': /session/a15a413670dbd32d691b439dee588d77/url
[2025-04-14T17:32:51.217+0000] {connectionpool.py:868} WARNING - Retrying (Retry(total=0, connect=None, read=None, redirect=None, status=None)) after connection broken by 'NewConnectionError('<urllib3.connection.HTTPConnection object at 0x7f0ec00df1a0>: Failed to establish a new connection: [Errno 111] Connection refused')': /session/d4792fc020ce44acf03cb058b0ac3794/url
[2025-04-14T17:32:51.236+0000] {SaveLinkBatdongsan.py:105} WARNING - Attempt 4 failed: HTTPConnectionPool(host='localhost', port=42983): Max retries exceeded with url: /session/d4792fc020ce44acf03cb058b0ac3794/url (Caused by NewConnectionError('<urllib3.connection.HTTPConnection object at 0x7f0ec00df410>: Failed to establish a new connection: [Errno 111] Connection refused'))
[2025-04-14T17:32:51.232+0000] {connectionpool.py:868} WARNING - Retrying (Retry(total=0, connect=None, read=None, redirect=None, status=None)) after connection broken by 'NewConnectionError('<urllib3.connection.HTTPConnection object at 0x7f0ec00dee70>: Failed to establish a new connection: [Errno 111] Connection refused')': /session/a15a413670dbd32d691b439dee588d77/url
[2025-04-14T17:32:51.245+0000] {SaveLinkBatdongsan.py:105} WARNING - Attempt 4 failed: HTTPConnectionPool(host='localhost', port=49823): Max retries exceeded with url: /session/a15a413670dbd32d691b439dee588d77/url (Caused by NewConnectionError('<urllib3.connection.HTTPConnection object at 0x7f0ec00deed0>: Failed to establish a new connection: [Errno 111] Connection refused'))
[2025-04-14T17:32:51.708+0000] {SaveLinkBatdongsan.py:135} INFO - Scraping page 25: https://batdongsan.com.vn/nha-dat-ban/p25?gtn=7-ty&gcn=30-ty
[2025-04-14T17:33:01.090+0000] {connectionpool.py:868} WARNING - Retrying (Retry(total=2, connect=None, read=None, redirect=None, status=None)) after connection broken by 'NewConnectionError('<urllib3.connection.HTTPConnection object at 0x7f0ec00dfc20>: Failed to establish a new connection: [Errno 111] Connection refused')': /session/59da8b5137dfb5cadb68e7bf848e8314/url
[2025-04-14T17:33:01.098+0000] {connectionpool.py:868} WARNING - Retrying (Retry(total=1, connect=None, read=None, redirect=None, status=None)) after connection broken by 'NewConnectionError('<urllib3.connection.HTTPConnection object at 0x7f0ec00dfec0>: Failed to establish a new connection: [Errno 111] Connection refused')': /session/59da8b5137dfb5cadb68e7bf848e8314/url
[2025-04-14T17:33:01.105+0000] {connectionpool.py:868} WARNING - Retrying (Retry(total=0, connect=None, read=None, redirect=None, status=None)) after connection broken by 'NewConnectionError('<urllib3.connection.HTTPConnection object at 0x7f0ebbf103b0>: Failed to establish a new connection: [Errno 111] Connection refused')': /session/59da8b5137dfb5cadb68e7bf848e8314/url
[2025-04-14T17:33:01.112+0000] {SaveLinkBatdongsan.py:105} WARNING - Attempt 5 failed: HTTPConnectionPool(host='localhost', port=57597): Max retries exceeded with url: /session/59da8b5137dfb5cadb68e7bf848e8314/url (Caused by NewConnectionError('<urllib3.connection.HTTPConnection object at 0x7f0ebbf106e0>: Failed to establish a new connection: [Errno 111] Connection refused'))
[2025-04-14T17:33:01.129+0000] {connectionpool.py:868} WARNING - Retrying (Retry(total=2, connect=None, read=None, redirect=None, status=None)) after connection broken by 'NewConnectionError('<urllib3.connection.HTTPConnection object at 0x7f0ebbf109e0>: Failed to establish a new connection: [Errno 111] Connection refused')': /session/2c4871bc7066ce27dc562f81652666e7/url
[2025-04-14T17:33:01.134+0000] {connectionpool.py:868} WARNING - Retrying (Retry(total=1, connect=None, read=None, redirect=None, status=None)) after connection broken by 'NewConnectionError('<urllib3.connection.HTTPConnection object at 0x7f0ebbf10d40>: Failed to establish a new connection: [Errno 111] Connection refused')': /session/2c4871bc7066ce27dc562f81652666e7/url
[2025-04-14T17:33:01.136+0000] {connectionpool.py:868} WARNING - Retrying (Retry(total=0, connect=None, read=None, redirect=None, status=None)) after connection broken by 'NewConnectionError('<urllib3.connection.HTTPConnection object at 0x7f0ebbf111c0>: Failed to establish a new connection: [Errno 111] Connection refused')': /session/2c4871bc7066ce27dc562f81652666e7/url
[2025-04-14T17:33:01.149+0000] {SaveLinkBatdongsan.py:105} WARNING - Attempt 5 failed: HTTPConnectionPool(host='localhost', port=60457): Max retries exceeded with url: /session/2c4871bc7066ce27dc562f81652666e7/url (Caused by NewConnectionError('<urllib3.connection.HTTPConnection object at 0x7f0ebbf11460>: Failed to establish a new connection: [Errno 111] Connection refused'))
[2025-04-14T17:33:01.246+0000] {connectionpool.py:868} WARNING - Retrying (Retry(total=2, connect=None, read=None, redirect=None, status=None)) after connection broken by 'NewConnectionError('<urllib3.connection.HTTPConnection object at 0x7f0ebbf11910>: Failed to establish a new connection: [Errno 111] Connection refused')': /session/d4792fc020ce44acf03cb058b0ac3794/url
[2025-04-14T17:33:01.256+0000] {connectionpool.py:868} WARNING - Retrying (Retry(total=1, connect=None, read=None, redirect=None, status=None)) after connection broken by 'NewConnectionError('<urllib3.connection.HTTPConnection object at 0x7f0ec1281a90>: Failed to establish a new connection: [Errno 111] Connection refused')': /session/d4792fc020ce44acf03cb058b0ac3794/url
[2025-04-14T17:33:01.252+0000] {connectionpool.py:868} WARNING - Retrying (Retry(total=2, connect=None, read=None, redirect=None, status=None)) after connection broken by 'NewConnectionError('<urllib3.connection.HTTPConnection object at 0x7f0ebbf11d30>: Failed to establish a new connection: [Errno 111] Connection refused')': /session/a15a413670dbd32d691b439dee588d77/url
[2025-04-14T17:33:01.267+0000] {connectionpool.py:868} WARNING - Retrying (Retry(total=0, connect=None, read=None, redirect=None, status=None)) after connection broken by 'NewConnectionError('<urllib3.connection.HTTPConnection object at 0x7f0ebbf12120>: Failed to establish a new connection: [Errno 111] Connection refused')': /session/d4792fc020ce44acf03cb058b0ac3794/url
[2025-04-14T17:33:01.263+0000] {connectionpool.py:868} WARNING - Retrying (Retry(total=1, connect=None, read=None, redirect=None, status=None)) after connection broken by 'NewConnectionError('<urllib3.connection.HTTPConnection object at 0x7f0ebbf12330>: Failed to establish a new connection: [Errno 111] Connection refused')': /session/a15a413670dbd32d691b439dee588d77/url
[2025-04-14T17:33:01.278+0000] {connectionpool.py:868} WARNING - Retrying (Retry(total=0, connect=None, read=None, redirect=None, status=None)) after connection broken by 'NewConnectionError('<urllib3.connection.HTTPConnection object at 0x7f0ebbf12930>: Failed to establish a new connection: [Errno 111] Connection refused')': /session/a15a413670dbd32d691b439dee588d77/url
[2025-04-14T17:33:01.289+0000] {SaveLinkBatdongsan.py:105} WARNING - Attempt 5 failed: HTTPConnectionPool(host='localhost', port=49823): Max retries exceeded with url: /session/a15a413670dbd32d691b439dee588d77/url (Caused by NewConnectionError('<urllib3.connection.HTTPConnection object at 0x7f0ebbf12c00>: Failed to establish a new connection: [Errno 111] Connection refused'))
[2025-04-14T17:33:01.290+0000] {SaveLinkBatdongsan.py:105} WARNING - Attempt 5 failed: HTTPConnectionPool(host='localhost', port=42983): Max retries exceeded with url: /session/d4792fc020ce44acf03cb058b0ac3794/url (Caused by NewConnectionError('<urllib3.connection.HTTPConnection object at 0x7f0ebbf125a0>: Failed to establish a new connection: [Errno 111] Connection refused'))
[2025-04-14T17:33:04.166+0000] {SaveLinkBatdongsan.py:141} INFO - Found 20 links on page 25
[2025-04-14T17:33:04.837+0000] {SaveLinkBatdongsan.py:135} INFO - Scraping page 26: https://batdongsan.com.vn/nha-dat-ban/p26?gtn=7-ty&gcn=30-ty
[2025-04-14T17:33:11.116+0000] {connectionpool.py:868} WARNING - Retrying (Retry(total=2, connect=None, read=None, redirect=None, status=None)) after connection broken by 'NewConnectionError('<urllib3.connection.HTTPConnection object at 0x7f0ec3098320>: Failed to establish a new connection: [Errno 111] Connection refused')': /session/59da8b5137dfb5cadb68e7bf848e8314/url
[2025-04-14T17:33:11.119+0000] {connectionpool.py:868} WARNING - Retrying (Retry(total=1, connect=None, read=None, redirect=None, status=None)) after connection broken by 'NewConnectionError('<urllib3.connection.HTTPConnection object at 0x7f0ec3099a60>: Failed to establish a new connection: [Errno 111] Connection refused')': /session/59da8b5137dfb5cadb68e7bf848e8314/url
[2025-04-14T17:33:11.125+0000] {connectionpool.py:868} WARNING - Retrying (Retry(total=0, connect=None, read=None, redirect=None, status=None)) after connection broken by 'NewConnectionError('<urllib3.connection.HTTPConnection object at 0x7f0ec3098890>: Failed to establish a new connection: [Errno 111] Connection refused')': /session/59da8b5137dfb5cadb68e7bf848e8314/url
[2025-04-14T17:33:11.129+0000] {SaveLinkBatdongsan.py:105} WARNING - Attempt 6 failed: HTTPConnectionPool(host='localhost', port=57597): Max retries exceeded with url: /session/59da8b5137dfb5cadb68e7bf848e8314/url (Caused by NewConnectionError('<urllib3.connection.HTTPConnection object at 0x7f0ec1513e30>: Failed to establish a new connection: [Errno 111] Connection refused'))
[2025-04-14T17:33:11.157+0000] {connectionpool.py:868} WARNING - Retrying (Retry(total=2, connect=None, read=None, redirect=None, status=None)) after connection broken by 'NewConnectionError('<urllib3.connection.HTTPConnection object at 0x7f0ec1513980>: Failed to establish a new connection: [Errno 111] Connection refused')': /session/2c4871bc7066ce27dc562f81652666e7/url
[2025-04-14T17:33:11.166+0000] {connectionpool.py:868} WARNING - Retrying (Retry(total=1, connect=None, read=None, redirect=None, status=None)) after connection broken by 'NewConnectionError('<urllib3.connection.HTTPConnection object at 0x7f0ec1513cb0>: Failed to establish a new connection: [Errno 111] Connection refused')': /session/2c4871bc7066ce27dc562f81652666e7/url
[2025-04-14T17:33:11.170+0000] {connectionpool.py:868} WARNING - Retrying (Retry(total=0, connect=None, read=None, redirect=None, status=None)) after connection broken by 'NewConnectionError('<urllib3.connection.HTTPConnection object at 0x7f0ec1513da0>: Failed to establish a new connection: [Errno 111] Connection refused')': /session/2c4871bc7066ce27dc562f81652666e7/url
[2025-04-14T17:33:11.173+0000] {SaveLinkBatdongsan.py:105} WARNING - Attempt 6 failed: HTTPConnectionPool(host='localhost', port=60457): Max retries exceeded with url: /session/2c4871bc7066ce27dc562f81652666e7/url (Caused by NewConnectionError('<urllib3.connection.HTTPConnection object at 0x7f0ec15138c0>: Failed to establish a new connection: [Errno 111] Connection refused'))
[2025-04-14T17:33:11.299+0000] {connectionpool.py:868} WARNING - Retrying (Retry(total=2, connect=None, read=None, redirect=None, status=None)) after connection broken by 'NewConnectionError('<urllib3.connection.HTTPConnection object at 0x7f0ec1513590>: Failed to establish a new connection: [Errno 111] Connection refused')': /session/a15a413670dbd32d691b439dee588d77/url
[2025-04-14T17:33:11.301+0000] {connectionpool.py:868} WARNING - Retrying (Retry(total=2, connect=None, read=None, redirect=None, status=None)) after connection broken by 'NewConnectionError('<urllib3.connection.HTTPConnection object at 0x7f0ec15131d0>: Failed to establish a new connection: [Errno 111] Connection refused')': /session/d4792fc020ce44acf03cb058b0ac3794/url
[2025-04-14T17:33:11.308+0000] {connectionpool.py:868} WARNING - Retrying (Retry(total=1, connect=None, read=None, redirect=None, status=None)) after connection broken by 'NewConnectionError('<urllib3.connection.HTTPConnection object at 0x7f0ec1512960>: Failed to establish a new connection: [Errno 111] Connection refused')': /session/d4792fc020ce44acf03cb058b0ac3794/url
[2025-04-14T17:33:11.307+0000] {connectionpool.py:868} WARNING - Retrying (Retry(total=1, connect=None, read=None, redirect=None, status=None)) after connection broken by 'NewConnectionError('<urllib3.connection.HTTPConnection object at 0x7f0ec1512d80>: Failed to establish a new connection: [Errno 111] Connection refused')': /session/a15a413670dbd32d691b439dee588d77/url
[2025-04-14T17:33:11.318+0000] {connectionpool.py:868} WARNING - Retrying (Retry(total=0, connect=None, read=None, redirect=None, status=None)) after connection broken by 'NewConnectionError('<urllib3.connection.HTTPConnection object at 0x7f0ec15126f0>: Failed to establish a new connection: [Errno 111] Connection refused')': /session/d4792fc020ce44acf03cb058b0ac3794/url
[2025-04-14T17:33:11.320+0000] {connectionpool.py:868} WARNING - Retrying (Retry(total=0, connect=None, read=None, redirect=None, status=None)) after connection broken by 'NewConnectionError('<urllib3.connection.HTTPConnection object at 0x7f0ec1512240>: Failed to establish a new connection: [Errno 111] Connection refused')': /session/a15a413670dbd32d691b439dee588d77/url
[2025-04-14T17:33:11.321+0000] {SaveLinkBatdongsan.py:105} WARNING - Attempt 6 failed: HTTPConnectionPool(host='localhost', port=42983): Max retries exceeded with url: /session/d4792fc020ce44acf03cb058b0ac3794/url (Caused by NewConnectionError('<urllib3.connection.HTTPConnection object at 0x7f0ec1512180>: Failed to establish a new connection: [Errno 111] Connection refused'))
[2025-04-14T17:33:11.324+0000] {SaveLinkBatdongsan.py:105} WARNING - Attempt 6 failed: HTTPConnectionPool(host='localhost', port=49823): Max retries exceeded with url: /session/a15a413670dbd32d691b439dee588d77/url (Caused by NewConnectionError('<urllib3.connection.HTTPConnection object at 0x7f0ec1511dc0>: Failed to establish a new connection: [Errno 111] Connection refused'))
[2025-04-14T17:33:12.123+0000] {SaveLinkBatdongsan.py:141} INFO - Found 20 links on page 26
[2025-04-14T17:33:12.919+0000] {SaveLinkBatdongsan.py:135} INFO - Scraping page 27: https://batdongsan.com.vn/nha-dat-ban/p27?gtn=7-ty&gcn=30-ty
[2025-04-14T17:33:20.878+0000] {process_utils.py:150} WARNING - process psutil.Process(pid=3110, name='chromedriver', status='zombie', started='17:32:02') did not respond to SIGTERM. Trying SIGKILL
[2025-04-14T17:33:20.882+0000] {process_utils.py:150} WARNING - process psutil.Process(pid=193, name='airflow task ru', status='sleeping', started='17:31:23') did not respond to SIGTERM. Trying SIGKILL
[2025-04-14T17:33:20.886+0000] {process_utils.py:150} WARNING - process psutil.Process(pid=3487, name='chromedriver', status='zombie', started='17:32:11') did not respond to SIGTERM. Trying SIGKILL
[2025-04-14T17:33:20.889+0000] {process_utils.py:150} WARNING - process psutil.Process(pid=4172, name='chromedriver', status='zombie', started='17:32:14') did not respond to SIGTERM. Trying SIGKILL
[2025-04-14T17:33:20.899+0000] {process_utils.py:150} WARNING - process psutil.Process(pid=3473, name='chromedriver', status='zombie', started='17:32:11') did not respond to SIGTERM. Trying SIGKILL
[2025-04-14T17:33:20.903+0000] {process_utils.py:150} WARNING - process psutil.Process(pid=3436, name='chromedriver', status='zombie', started='17:32:10') did not respond to SIGTERM. Trying SIGKILL
[2025-04-14T17:33:20.912+0000] {process_utils.py:87} INFO - Sending the signal 9 to group 193
[2025-04-14T17:33:21.029+0000] {process_utils.py:80} INFO - Process psutil.Process(pid=3110, name='chromedriver', status='terminated', started='17:32:02') (3110) terminated with exit code None
[2025-04-14T17:33:21.031+0000] {process_utils.py:80} INFO - Process psutil.Process(pid=193, name='airflow task ru', status='terminated', exitcode=<Negsignal.SIGKILL: -9>, started='17:31:23') (193) terminated with exit code -9
[2025-04-14T17:33:21.032+0000] {process_utils.py:80} INFO - Process psutil.Process(pid=3487, name='chromedriver', status='terminated', started='17:32:11') (3487) terminated with exit code None
[2025-04-14T17:33:21.032+0000] {process_utils.py:80} INFO - Process psutil.Process(pid=3473, name='chromedriver', status='terminated', started='17:32:11') (3473) terminated with exit code None
[2025-04-14T17:33:21.033+0000] {process_utils.py:80} INFO - Process psutil.Process(pid=4172, name='chromedriver', status='terminated', started='17:32:14') (4172) terminated with exit code None
[2025-04-14T17:33:21.036+0000] {process_utils.py:80} INFO - Process psutil.Process(pid=3436, name='chromedriver', status='terminated', started='17:32:10') (3436) terminated with exit code None
[2025-04-14T17:33:21.038+0000] {standard_task_runner.py:190} ERROR - ('Job 2 was killed before it finished (likely due to running out of memory)', 'For more information, see https://***.apache.org/docs/apache-***/stable/troubleshooting.html#LocalTaskJob-killed')
