[2025-04-14T15:10:52.980+0000] {local_task_job_runner.py:123} INFO - ::group::Pre task execution logs
[2025-04-14T15:10:52.995+0000] {taskinstance.py:2614} INFO - Dependencies all met for dep_context=non-requeueable deps ti=<TaskInstance: batdongsan_scraping.save_links manual__2025-04-14T15:10:51.596165+00:00 [queued]>
[2025-04-14T15:10:53.001+0000] {taskinstance.py:2614} INFO - Dependencies all met for dep_context=requeueable deps ti=<TaskInstance: batdongsan_scraping.save_links manual__2025-04-14T15:10:51.596165+00:00 [queued]>
[2025-04-14T15:10:53.002+0000] {taskinstance.py:2867} INFO - Starting attempt 1 of 2
[2025-04-14T15:10:53.012+0000] {taskinstance.py:2890} INFO - Executing <Task(PythonOperator): save_links> on 2025-04-14 15:10:51.596165+00:00
[2025-04-14T15:10:53.022+0000] {standard_task_runner.py:104} INFO - Running: ['***', 'tasks', 'run', 'batdongsan_scraping', 'save_links', 'manual__2025-04-14T15:10:51.596165+00:00', '--job-id', '2', '--raw', '--subdir', 'DAGS_FOLDER/batdongsan_scraping_dag.py', '--cfg-path', '/tmp/tmp2d8_swhi']
[2025-04-14T15:10:53.025+0000] {standard_task_runner.py:105} INFO - Job 2: Subtask save_links
[2025-04-14T15:10:53.027+0000] {logging_mixin.py:190} WARNING - /home/***/.local/lib/python3.12/site-packages/***/task/task_runner/standard_task_runner.py:70 DeprecationWarning: This process (pid=181) is multi-threaded, use of fork() may lead to deadlocks in the child.
[2025-04-14T15:10:53.028+0000] {standard_task_runner.py:72} INFO - Started process 184 to run task
[2025-04-14T15:10:53.072+0000] {task_command.py:467} INFO - Running <TaskInstance: batdongsan_scraping.save_links manual__2025-04-14T15:10:51.596165+00:00 [running]> on host bc96f256ac97
[2025-04-14T15:10:53.154+0000] {taskinstance.py:3134} INFO - Exporting env vars: AIRFLOW_CTX_DAG_OWNER='***' AIRFLOW_CTX_DAG_ID='batdongsan_scraping' AIRFLOW_CTX_TASK_ID='save_links' AIRFLOW_CTX_EXECUTION_DATE='2025-04-14T15:10:51.596165+00:00' AIRFLOW_CTX_TRY_NUMBER='1' AIRFLOW_CTX_DAG_RUN_ID='manual__2025-04-14T15:10:51.596165+00:00'
[2025-04-14T15:10:53.155+0000] {taskinstance.py:732} INFO - ::endgroup::
[2025-04-14T15:10:53.185+0000] {SaveLinkBatdongsan.py:114} ERROR - Error scraping page 1: Message: Unable to obtain driver for chrome using Selenium Manager.; For documentation on this error, please visit: https://www.selenium.dev/documentation/webdriver/troubleshooting/errors/driver_location

[2025-04-14T15:10:53.185+0000] {taskinstance.py:3313} ERROR - Task failed with exception
Traceback (most recent call last):
  File "/home/airflow/.local/lib/python3.12/site-packages/selenium/webdriver/common/driver_finder.py", line 38, in get_path
    path = SeleniumManager().driver_location(options) if path is None else path
           ^^^^^^^^^^^^^^^^^^^^^^^^^^^^^^^^^^^^^^^^^^
  File "/home/airflow/.local/lib/python3.12/site-packages/selenium/webdriver/common/selenium_manager.py", line 89, in driver_location
    args = [str(self.get_binary()), "--browser", browser]
                ^^^^^^^^^^^^^^^^^
  File "/home/airflow/.local/lib/python3.12/site-packages/selenium/webdriver/common/selenium_manager.py", line 63, in get_binary
    raise WebDriverException(f"Unsupported platform/architecture combination: {sys.platform}/{arch}")
selenium.common.exceptions.WebDriverException: Message: Unsupported platform/architecture combination: linux/aarch64


The above exception was the direct cause of the following exception:

Traceback (most recent call last):
  File "/opt/airflow/dags/../scripts/SaveLinkBatdongsan.py", line 89, in scrape_page
    driver = webdriver.Chrome(options=self.chrome_options)
             ^^^^^^^^^^^^^^^^^^^^^^^^^^^^^^^^^^^^^^^^^^^^^
  File "/home/airflow/.local/lib/python3.12/site-packages/selenium/webdriver/chrome/webdriver.py", line 45, in __init__
    super().__init__(
  File "/home/airflow/.local/lib/python3.12/site-packages/selenium/webdriver/chromium/webdriver.py", line 49, in __init__
    self.service.path = DriverFinder.get_path(self.service, options)
                        ^^^^^^^^^^^^^^^^^^^^^^^^^^^^^^^^^^^^^^^^^^^^
  File "/home/airflow/.local/lib/python3.12/site-packages/selenium/webdriver/common/driver_finder.py", line 41, in get_path
    raise NoSuchDriverException(msg) from err
selenium.common.exceptions.NoSuchDriverException: Message: Unable to obtain driver for chrome using Selenium Manager.; For documentation on this error, please visit: https://www.selenium.dev/documentation/webdriver/troubleshooting/errors/driver_location


During handling of the above exception, another exception occurred:

Traceback (most recent call last):
  File "/home/airflow/.local/lib/python3.12/site-packages/airflow/models/taskinstance.py", line 768, in _execute_task
    result = _execute_callable(context=context, **execute_callable_kwargs)
             ^^^^^^^^^^^^^^^^^^^^^^^^^^^^^^^^^^^^^^^^^^^^^^^^^^^^^^^^^^^^^
  File "/home/airflow/.local/lib/python3.12/site-packages/airflow/models/taskinstance.py", line 734, in _execute_callable
    return ExecutionCallableRunner(
           ^^^^^^^^^^^^^^^^^^^^^^^^
  File "/home/airflow/.local/lib/python3.12/site-packages/airflow/utils/operator_helpers.py", line 252, in run
    return self.func(*args, **kwargs)
           ^^^^^^^^^^^^^^^^^^^^^^^^^^
  File "/home/airflow/.local/lib/python3.12/site-packages/airflow/models/baseoperator.py", line 424, in wrapper
    return func(self, *args, **kwargs)
           ^^^^^^^^^^^^^^^^^^^^^^^^^^^
  File "/home/airflow/.local/lib/python3.12/site-packages/airflow/operators/python.py", line 238, in execute
    return_value = self.execute_callable()
                   ^^^^^^^^^^^^^^^^^^^^^^^
  File "/home/airflow/.local/lib/python3.12/site-packages/airflow/operators/python.py", line 256, in execute_callable
    return runner.run(*self.op_args, **self.op_kwargs)
           ^^^^^^^^^^^^^^^^^^^^^^^^^^^^^^^^^^^^^^^^^^^
  File "/home/airflow/.local/lib/python3.12/site-packages/airflow/utils/operator_helpers.py", line 252, in run
    return self.func(*args, **kwargs)
           ^^^^^^^^^^^^^^^^^^^^^^^^^^
  File "/opt/airflow/dags/batdongsan_scraping_dag.py", line 40, in save_links_task
    scraper.run()
  File "/opt/airflow/dags/../scripts/SaveLinkBatdongsan.py", line 206, in run
    self.scrape_all_pages()
  File "/opt/airflow/dags/../scripts/SaveLinkBatdongsan.py", line 127, in scrape_all_pages
    page_errors = self.scrape_page(page_index)
                  ^^^^^^^^^^^^^^^^^^^^^^^^^^^^
  File "/opt/airflow/dags/../scripts/SaveLinkBatdongsan.py", line 115, in scrape_page
    error_urls.append(full_path)
                      ^^^^^^^^^
UnboundLocalError: cannot access local variable 'full_path' where it is not associated with a value
[2025-04-14T15:10:53.198+0000] {taskinstance.py:1226} INFO - Marking task as UP_FOR_RETRY. dag_id=batdongsan_scraping, task_id=save_links, run_id=manual__2025-04-14T15:10:51.596165+00:00, execution_date=20250414T151051, start_date=20250414T151052, end_date=20250414T151053
[2025-04-14T15:10:53.217+0000] {taskinstance.py:341} INFO - ::group::Post task execution logs
[2025-04-14T15:10:53.217+0000] {standard_task_runner.py:124} ERROR - Failed to execute job 2 for task save_links (cannot access local variable 'full_path' where it is not associated with a value; 184)
Traceback (most recent call last):
  File "/home/airflow/.local/lib/python3.12/site-packages/selenium/webdriver/common/driver_finder.py", line 38, in get_path
    path = SeleniumManager().driver_location(options) if path is None else path
           ^^^^^^^^^^^^^^^^^^^^^^^^^^^^^^^^^^^^^^^^^^
  File "/home/airflow/.local/lib/python3.12/site-packages/selenium/webdriver/common/selenium_manager.py", line 89, in driver_location
    args = [str(self.get_binary()), "--browser", browser]
                ^^^^^^^^^^^^^^^^^
  File "/home/airflow/.local/lib/python3.12/site-packages/selenium/webdriver/common/selenium_manager.py", line 63, in get_binary
    raise WebDriverException(f"Unsupported platform/architecture combination: {sys.platform}/{arch}")
selenium.common.exceptions.WebDriverException: Message: Unsupported platform/architecture combination: linux/aarch64


The above exception was the direct cause of the following exception:

Traceback (most recent call last):
  File "/opt/airflow/dags/../scripts/SaveLinkBatdongsan.py", line 89, in scrape_page
    driver = webdriver.Chrome(options=self.chrome_options)
             ^^^^^^^^^^^^^^^^^^^^^^^^^^^^^^^^^^^^^^^^^^^^^
  File "/home/airflow/.local/lib/python3.12/site-packages/selenium/webdriver/chrome/webdriver.py", line 45, in __init__
    super().__init__(
  File "/home/airflow/.local/lib/python3.12/site-packages/selenium/webdriver/chromium/webdriver.py", line 49, in __init__
    self.service.path = DriverFinder.get_path(self.service, options)
                        ^^^^^^^^^^^^^^^^^^^^^^^^^^^^^^^^^^^^^^^^^^^^
  File "/home/airflow/.local/lib/python3.12/site-packages/selenium/webdriver/common/driver_finder.py", line 41, in get_path
    raise NoSuchDriverException(msg) from err
selenium.common.exceptions.NoSuchDriverException: Message: Unable to obtain driver for chrome using Selenium Manager.; For documentation on this error, please visit: https://www.selenium.dev/documentation/webdriver/troubleshooting/errors/driver_location


During handling of the above exception, another exception occurred:

Traceback (most recent call last):
  File "/home/airflow/.local/lib/python3.12/site-packages/airflow/task/task_runner/standard_task_runner.py", line 117, in _start_by_fork
    ret = args.func(args, dag=self.dag)
          ^^^^^^^^^^^^^^^^^^^^^^^^^^^^^
  File "/home/airflow/.local/lib/python3.12/site-packages/airflow/cli/cli_config.py", line 49, in command
    return func(*args, **kwargs)
           ^^^^^^^^^^^^^^^^^^^^^
  File "/home/airflow/.local/lib/python3.12/site-packages/airflow/utils/cli.py", line 116, in wrapper
    return f(*args, **kwargs)
           ^^^^^^^^^^^^^^^^^^
  File "/home/airflow/.local/lib/python3.12/site-packages/airflow/cli/commands/task_command.py", line 483, in task_run
    task_return_code = _run_task_by_selected_method(args, _dag, ti)
                       ^^^^^^^^^^^^^^^^^^^^^^^^^^^^^^^^^^^^^^^^^^^^
  File "/home/airflow/.local/lib/python3.12/site-packages/airflow/cli/commands/task_command.py", line 256, in _run_task_by_selected_method
    return _run_raw_task(args, ti)
           ^^^^^^^^^^^^^^^^^^^^^^^
  File "/home/airflow/.local/lib/python3.12/site-packages/airflow/cli/commands/task_command.py", line 341, in _run_raw_task
    return ti._run_raw_task(
           ^^^^^^^^^^^^^^^^^
  File "/home/airflow/.local/lib/python3.12/site-packages/airflow/utils/session.py", line 97, in wrapper
    return func(*args, session=session, **kwargs)
           ^^^^^^^^^^^^^^^^^^^^^^^^^^^^^^^^^^^^^^
  File "/home/airflow/.local/lib/python3.12/site-packages/airflow/models/taskinstance.py", line 3006, in _run_raw_task
    return _run_raw_task(
           ^^^^^^^^^^^^^^
  File "/home/airflow/.local/lib/python3.12/site-packages/airflow/models/taskinstance.py", line 274, in _run_raw_task
    TaskInstance._execute_task_with_callbacks(
  File "/home/airflow/.local/lib/python3.12/site-packages/airflow/models/taskinstance.py", line 3161, in _execute_task_with_callbacks
    result = self._execute_task(context, task_orig)
             ^^^^^^^^^^^^^^^^^^^^^^^^^^^^^^^^^^^^^^
  File "/home/airflow/.local/lib/python3.12/site-packages/airflow/models/taskinstance.py", line 3185, in _execute_task
    return _execute_task(self, context, task_orig)
           ^^^^^^^^^^^^^^^^^^^^^^^^^^^^^^^^^^^^^^^
  File "/home/airflow/.local/lib/python3.12/site-packages/airflow/models/taskinstance.py", line 768, in _execute_task
    result = _execute_callable(context=context, **execute_callable_kwargs)
             ^^^^^^^^^^^^^^^^^^^^^^^^^^^^^^^^^^^^^^^^^^^^^^^^^^^^^^^^^^^^^
  File "/home/airflow/.local/lib/python3.12/site-packages/airflow/models/taskinstance.py", line 734, in _execute_callable
    return ExecutionCallableRunner(
           ^^^^^^^^^^^^^^^^^^^^^^^^
  File "/home/airflow/.local/lib/python3.12/site-packages/airflow/utils/operator_helpers.py", line 252, in run
    return self.func(*args, **kwargs)
           ^^^^^^^^^^^^^^^^^^^^^^^^^^
  File "/home/airflow/.local/lib/python3.12/site-packages/airflow/models/baseoperator.py", line 424, in wrapper
    return func(self, *args, **kwargs)
           ^^^^^^^^^^^^^^^^^^^^^^^^^^^
  File "/home/airflow/.local/lib/python3.12/site-packages/airflow/operators/python.py", line 238, in execute
    return_value = self.execute_callable()
                   ^^^^^^^^^^^^^^^^^^^^^^^
  File "/home/airflow/.local/lib/python3.12/site-packages/airflow/operators/python.py", line 256, in execute_callable
    return runner.run(*self.op_args, **self.op_kwargs)
           ^^^^^^^^^^^^^^^^^^^^^^^^^^^^^^^^^^^^^^^^^^^
  File "/home/airflow/.local/lib/python3.12/site-packages/airflow/utils/operator_helpers.py", line 252, in run
    return self.func(*args, **kwargs)
           ^^^^^^^^^^^^^^^^^^^^^^^^^^
  File "/opt/airflow/dags/batdongsan_scraping_dag.py", line 40, in save_links_task
    scraper.run()
  File "/opt/airflow/dags/../scripts/SaveLinkBatdongsan.py", line 206, in run
    self.scrape_all_pages()
  File "/opt/airflow/dags/../scripts/SaveLinkBatdongsan.py", line 127, in scrape_all_pages
    page_errors = self.scrape_page(page_index)
                  ^^^^^^^^^^^^^^^^^^^^^^^^^^^^
  File "/opt/airflow/dags/../scripts/SaveLinkBatdongsan.py", line 115, in scrape_page
    error_urls.append(full_path)
                      ^^^^^^^^^
UnboundLocalError: cannot access local variable 'full_path' where it is not associated with a value
[2025-04-14T15:10:53.253+0000] {local_task_job_runner.py:266} INFO - Task exited with return code 1
[2025-04-14T15:10:53.271+0000] {taskinstance.py:3901} INFO - 0 downstream tasks scheduled from follow-on schedule check
[2025-04-14T15:10:53.273+0000] {local_task_job_runner.py:245} INFO - ::endgroup::
