[2025-04-14T15:24:06.059+0000] {local_task_job_runner.py:123} INFO - ::group::Pre task execution logs
[2025-04-14T15:24:06.070+0000] {taskinstance.py:2614} INFO - Dependencies all met for dep_context=non-requeueable deps ti=<TaskInstance: batdongsan_scraping.save_links scheduled__2025-04-13T00:00:00+00:00 [queued]>
[2025-04-14T15:24:06.075+0000] {taskinstance.py:2614} INFO - Dependencies all met for dep_context=requeueable deps ti=<TaskInstance: batdongsan_scraping.save_links scheduled__2025-04-13T00:00:00+00:00 [queued]>
[2025-04-14T15:24:06.076+0000] {taskinstance.py:2867} INFO - Starting attempt 2 of 4
[2025-04-14T15:24:06.083+0000] {taskinstance.py:2890} INFO - Executing <Task(PythonOperator): save_links> on 2025-04-13 00:00:00+00:00
[2025-04-14T15:24:06.090+0000] {standard_task_runner.py:104} INFO - Running: ['***', 'tasks', 'run', 'batdongsan_scraping', 'save_links', 'scheduled__2025-04-13T00:00:00+00:00', '--job-id', '5', '--raw', '--subdir', 'DAGS_FOLDER/batdongsan_scraping_dag.py', '--cfg-path', '/tmp/tmpjipx9581']
[2025-04-14T15:24:06.092+0000] {logging_mixin.py:190} WARNING - /home/***/.local/lib/python3.12/site-packages/***/task/task_runner/standard_task_runner.py:70 DeprecationWarning: This process (pid=1060) is multi-threaded, use of fork() may lead to deadlocks in the child.
[2025-04-14T15:24:06.092+0000] {standard_task_runner.py:105} INFO - Job 5: Subtask save_links
[2025-04-14T15:24:06.092+0000] {standard_task_runner.py:72} INFO - Started process 1183 to run task
[2025-04-14T15:24:06.125+0000] {task_command.py:467} INFO - Running <TaskInstance: batdongsan_scraping.save_links scheduled__2025-04-13T00:00:00+00:00 [running]> on host 932270897c9d
[2025-04-14T15:24:06.199+0000] {taskinstance.py:3134} INFO - Exporting env vars: AIRFLOW_CTX_DAG_OWNER='***' AIRFLOW_CTX_DAG_ID='batdongsan_scraping' AIRFLOW_CTX_TASK_ID='save_links' AIRFLOW_CTX_EXECUTION_DATE='2025-04-13T00:00:00+00:00' AIRFLOW_CTX_TRY_NUMBER='2' AIRFLOW_CTX_DAG_RUN_ID='scheduled__2025-04-13T00:00:00+00:00'
[2025-04-14T15:24:06.200+0000] {taskinstance.py:732} INFO - ::endgroup::
[2025-04-14T15:24:06.241+0000] {SaveLinkBatdongsan.py:111} INFO - Loaded 60334 existing links
[2025-04-14T15:24:06.674+0000] {SaveLinkBatdongsan.py:127} INFO - Scraping page 1: https://batdongsan.com.vn/nha-dat-ban/p1?gtn=7-ty&gcn=30-ty
[2025-04-14T15:24:11.949+0000] {SaveLinkBatdongsan.py:133} INFO - Found 20 links on page 1
[2025-04-14T15:24:12.476+0000] {SaveLinkBatdongsan.py:127} INFO - Scraping page 2: https://batdongsan.com.vn/nha-dat-ban/p2?gtn=7-ty&gcn=30-ty
[2025-04-14T15:24:16.467+0000] {local_task_job_runner.py:346} WARNING - State of this instance has been externally set to failed. Terminating instance.
[2025-04-14T15:24:16.476+0000] {local_task_job_runner.py:245} INFO - ::endgroup::
[2025-04-14T15:24:16.483+0000] {process_utils.py:132} INFO - Sending 15 to group 1183. PIDs of all processes in the group: [1506, 1520, 1542, 1543, 1564, 1579, 1619, 1629, 1672, 1563, 1183]
[2025-04-14T15:24:16.484+0000] {process_utils.py:87} INFO - Sending the signal 15 to group 1183
[2025-04-14T15:24:16.489+0000] {taskinstance.py:3094} ERROR - Received SIGTERM. Terminating subprocesses.
[2025-04-14T15:24:16.543+0000] {taskinstance.py:3095} ERROR - Stacktrace: 
  File "/home/***/.local/bin/***", line 8, in <module>
    sys.exit(main())
  File "/home/***/.local/lib/python3.12/site-packages/***/__main__.py", line 62, in main
    args.func(args)
  File "/home/***/.local/lib/python3.12/site-packages/***/cli/cli_config.py", line 49, in command
    return func(*args, **kwargs)
  File "/home/***/.local/lib/python3.12/site-packages/***/utils/cli.py", line 116, in wrapper
    return f(*args, **kwargs)
  File "/home/***/.local/lib/python3.12/site-packages/***/utils/providers_configuration_loader.py", line 55, in wrapped_function
    return func(*args, **kwargs)
  File "/home/***/.local/lib/python3.12/site-packages/***/cli/commands/scheduler_command.py", line 56, in scheduler
    run_command_with_daemon_option(
  File "/home/***/.local/lib/python3.12/site-packages/***/cli/commands/daemon_utils.py", line 86, in run_command_with_daemon_option
    callback()
  File "/home/***/.local/lib/python3.12/site-packages/***/cli/commands/scheduler_command.py", line 59, in <lambda>
    callback=lambda: _run_scheduler_job(args),
  File "/home/***/.local/lib/python3.12/site-packages/***/cli/commands/scheduler_command.py", line 47, in _run_scheduler_job
    run_job(job=job_runner.job, execute_callable=job_runner._execute)
  File "/home/***/.local/lib/python3.12/site-packages/***/utils/session.py", line 97, in wrapper
    return func(*args, session=session, **kwargs)
  File "/home/***/.local/lib/python3.12/site-packages/***/jobs/job.py", line 421, in run_job
    return execute_job(job, execute_callable=execute_callable)
  File "/home/***/.local/lib/python3.12/site-packages/***/jobs/job.py", line 450, in execute_job
    ret = execute_callable()
  File "/home/***/.local/lib/python3.12/site-packages/***/jobs/scheduler_job_runner.py", line 990, in _execute
    executor.start()
  File "/home/***/.local/lib/python3.12/site-packages/***/executors/local_executor.py", line 392, in start
    self.impl.start()
  File "/home/***/.local/lib/python3.12/site-packages/***/executors/local_executor.py", line 330, in start
    worker.start()
  File "/usr/local/lib/python3.12/multiprocessing/process.py", line 121, in start
    self._popen = self._Popen(self)
  File "/usr/local/lib/python3.12/multiprocessing/context.py", line 224, in _Popen
    return _default_context.get_context().Process._Popen(process_obj)
  File "/usr/local/lib/python3.12/multiprocessing/context.py", line 282, in _Popen
    return Popen(process_obj)
  File "/usr/local/lib/python3.12/multiprocessing/popen_fork.py", line 19, in __init__
    self._launch(process_obj)
  File "/usr/local/lib/python3.12/multiprocessing/popen_fork.py", line 71, in _launch
    code = process_obj._bootstrap(parent_sentinel=child_r)
  File "/usr/local/lib/python3.12/multiprocessing/process.py", line 314, in _bootstrap
    self.run()
  File "/home/***/.local/lib/python3.12/site-packages/***/executors/local_executor.py", line 80, in run
    return super().run()
  File "/usr/local/lib/python3.12/multiprocessing/process.py", line 108, in run
    self._target(*self._args, **self._kwargs)
  File "/home/***/.local/lib/python3.12/site-packages/***/traces/tracer.py", line 58, in wrapper
    return func(*args, **kwargs)
  File "/home/***/.local/lib/python3.12/site-packages/***/executors/local_executor.py", line 211, in do_work
    self.execute_work(key=key, command=command)
  File "/home/***/.local/lib/python3.12/site-packages/***/traces/tracer.py", line 58, in wrapper
    return func(*args, **kwargs)
  File "/home/***/.local/lib/python3.12/site-packages/***/executors/local_executor.py", line 100, in execute_work
    state = self._execute_work_in_fork(command)
  File "/home/***/.local/lib/python3.12/site-packages/***/traces/tracer.py", line 58, in wrapper
    return func(*args, **kwargs)
  File "/home/***/.local/lib/python3.12/site-packages/***/executors/local_executor.py", line 142, in _execute_work_in_fork
    args.func(args)
  File "/home/***/.local/lib/python3.12/site-packages/***/cli/cli_config.py", line 49, in command
    return func(*args, **kwargs)
  File "/home/***/.local/lib/python3.12/site-packages/***/utils/cli.py", line 116, in wrapper
    return f(*args, **kwargs)
  File "/home/***/.local/lib/python3.12/site-packages/***/cli/commands/task_command.py", line 483, in task_run
    task_return_code = _run_task_by_selected_method(args, _dag, ti)
  File "/home/***/.local/lib/python3.12/site-packages/***/cli/commands/task_command.py", line 254, in _run_task_by_selected_method
    return _run_task_by_local_task_job(args, ti)
  File "/home/***/.local/lib/python3.12/site-packages/***/cli/commands/task_command.py", line 322, in _run_task_by_local_task_job
    ret = run_job(job=job_runner.job, execute_callable=job_runner._execute)
  File "/home/***/.local/lib/python3.12/site-packages/***/utils/session.py", line 97, in wrapper
    return func(*args, session=session, **kwargs)
  File "/home/***/.local/lib/python3.12/site-packages/***/jobs/job.py", line 421, in run_job
    return execute_job(job, execute_callable=execute_callable)
  File "/home/***/.local/lib/python3.12/site-packages/***/jobs/job.py", line 450, in execute_job
    ret = execute_callable()
  File "/home/***/.local/lib/python3.12/site-packages/***/jobs/local_task_job_runner.py", line 171, in _execute
    self.task_runner.start()
  File "/home/***/.local/lib/python3.12/site-packages/***/task/task_runner/standard_task_runner.py", line 55, in start
    self.process = self._start_by_fork()
  File "/home/***/.local/lib/python3.12/site-packages/***/task/task_runner/standard_task_runner.py", line 117, in _start_by_fork
    ret = args.func(args, dag=self.dag)
  File "/home/***/.local/lib/python3.12/site-packages/***/cli/cli_config.py", line 49, in command
    return func(*args, **kwargs)
  File "/home/***/.local/lib/python3.12/site-packages/***/utils/cli.py", line 116, in wrapper
    return f(*args, **kwargs)
  File "/home/***/.local/lib/python3.12/site-packages/***/cli/commands/task_command.py", line 483, in task_run
    task_return_code = _run_task_by_selected_method(args, _dag, ti)
  File "/home/***/.local/lib/python3.12/site-packages/***/cli/commands/task_command.py", line 256, in _run_task_by_selected_method
    return _run_raw_task(args, ti)
  File "/home/***/.local/lib/python3.12/site-packages/***/cli/commands/task_command.py", line 341, in _run_raw_task
    return ti._run_raw_task(
  File "/home/***/.local/lib/python3.12/site-packages/***/utils/session.py", line 97, in wrapper
    return func(*args, session=session, **kwargs)
  File "/home/***/.local/lib/python3.12/site-packages/***/models/taskinstance.py", line 3006, in _run_raw_task
    return _run_raw_task(
  File "/home/***/.local/lib/python3.12/site-packages/***/models/taskinstance.py", line 274, in _run_raw_task
    TaskInstance._execute_task_with_callbacks(
  File "/home/***/.local/lib/python3.12/site-packages/***/models/taskinstance.py", line 3161, in _execute_task_with_callbacks
    result = self._execute_task(context, task_orig)
  File "/home/***/.local/lib/python3.12/site-packages/***/models/taskinstance.py", line 3185, in _execute_task
    return _execute_task(self, context, task_orig)
  File "/home/***/.local/lib/python3.12/site-packages/***/models/taskinstance.py", line 768, in _execute_task
    result = _execute_callable(context=context, **execute_callable_kwargs)
  File "/home/***/.local/lib/python3.12/site-packages/***/models/taskinstance.py", line 734, in _execute_callable
    return ExecutionCallableRunner(
  File "/home/***/.local/lib/python3.12/site-packages/***/utils/operator_helpers.py", line 252, in run
    return self.func(*args, **kwargs)
  File "/home/***/.local/lib/python3.12/site-packages/***/models/baseoperator.py", line 424, in wrapper
    return func(self, *args, **kwargs)
  File "/home/***/.local/lib/python3.12/site-packages/***/operators/python.py", line 238, in execute
    return_value = self.execute_callable()
  File "/home/***/.local/lib/python3.12/site-packages/***/operators/python.py", line 256, in execute_callable
    return runner.run(*self.op_args, **self.op_kwargs)
  File "/home/***/.local/lib/python3.12/site-packages/***/utils/operator_helpers.py", line 252, in run
    return self.func(*args, **kwargs)
  File "/opt/***/dags/batdongsan_scraping_dag.py", line 47, in save_links_task
    scraper.run()
  File "/opt/***/dags/../scripts/SaveLinkBatdongsan.py", line 240, in run
    self.scrape_all_pages()
  File "/opt/***/dags/../scripts/SaveLinkBatdongsan.py", line 161, in scrape_all_pages
    page_errors = self.scrape_page(page_index)
  File "/opt/***/dags/../scripts/SaveLinkBatdongsan.py", line 128, in scrape_page
    html_content = self.get_page_with_retries(driver, full_path)
  File "/opt/***/dags/../scripts/SaveLinkBatdongsan.py", line 95, in get_page_with_retries
    driver.get(url)
  File "/home/***/.local/lib/python3.12/site-packages/selenium/webdriver/remote/webdriver.py", line 356, in get
    self.execute(Command.GET, {"url": url})
  File "/home/***/.local/lib/python3.12/site-packages/selenium/webdriver/remote/webdriver.py", line 345, in execute
    response = self.command_executor.execute(driver_command, params)
  File "/home/***/.local/lib/python3.12/site-packages/selenium/webdriver/remote/remote_connection.py", line 302, in execute
    return self._request(command_info[0], url, body=data)
  File "/home/***/.local/lib/python3.12/site-packages/selenium/webdriver/remote/remote_connection.py", line 322, in _request
    response = self._conn.request(method, url, body=body, headers=headers)
  File "/home/***/.local/lib/python3.12/site-packages/urllib3/_request_methods.py", line 143, in request
    return self.request_encode_body(
  File "/home/***/.local/lib/python3.12/site-packages/urllib3/_request_methods.py", line 278, in request_encode_body
    return self.urlopen(method, url, **extra_kw)
  File "/home/***/.local/lib/python3.12/site-packages/urllib3/poolmanager.py", line 443, in urlopen
    response = conn.urlopen(method, u.request_uri, **kw)
  File "/home/***/.local/lib/python3.12/site-packages/urllib3/connectionpool.py", line 787, in urlopen
    response = self._make_request(
  File "/home/***/.local/lib/python3.12/site-packages/urllib3/connectionpool.py", line 534, in _make_request
    response = conn.getresponse()
  File "/home/***/.local/lib/python3.12/site-packages/urllib3/connection.py", line 516, in getresponse
    httplib_response = super().getresponse()
  File "/usr/local/lib/python3.12/http/client.py", line 1430, in getresponse
    response.begin()
  File "/usr/local/lib/python3.12/http/client.py", line 331, in begin
    version, status, reason = self._read_status()
  File "/usr/local/lib/python3.12/http/client.py", line 292, in _read_status
    line = str(self.fp.readline(_MAXLINE + 1), "iso-8859-1")
  File "/usr/local/lib/python3.12/socket.py", line 720, in readinto
    return self._sock.recv_into(b)
  File "/home/***/.local/lib/python3.12/site-packages/***/models/taskinstance.py", line 3095, in signal_handler
    self.log.error("Stacktrace: \n%s", "".join(traceback.format_stack()))

[2025-04-14T15:24:16.556+0000] {process_utils.py:80} INFO - Process psutil.Process(pid=1542, status='terminated', started='15:24:11') (1542) terminated with exit code None
[2025-04-14T15:24:16.562+0000] {process_utils.py:80} INFO - Process psutil.Process(pid=1564, status='terminated', started='15:24:11') (1564) terminated with exit code None
[2025-04-14T15:24:16.562+0000] {process_utils.py:80} INFO - Process psutil.Process(pid=1543, status='terminated', started='15:24:11') (1543) terminated with exit code None
[2025-04-14T15:24:16.563+0000] {connectionpool.py:868} WARNING - Retrying (Retry(total=2, connect=None, read=None, redirect=None, status=None)) after connection broken by 'NewConnectionError('<urllib3.connection.HTTPConnection object at 0xffff89789010>: Failed to establish a new connection: [Errno 111] Connection refused')': /session/70cfe529f8eaa96315933f26d430f1a0
[2025-04-14T15:24:16.564+0000] {connectionpool.py:868} WARNING - Retrying (Retry(total=1, connect=None, read=None, redirect=None, status=None)) after connection broken by 'NewConnectionError('<urllib3.connection.HTTPConnection object at 0xffff89789250>: Failed to establish a new connection: [Errno 111] Connection refused')': /session/70cfe529f8eaa96315933f26d430f1a0
[2025-04-14T15:24:16.564+0000] {connectionpool.py:868} WARNING - Retrying (Retry(total=0, connect=None, read=None, redirect=None, status=None)) after connection broken by 'NewConnectionError('<urllib3.connection.HTTPConnection object at 0xffff89789580>: Failed to establish a new connection: [Errno 111] Connection refused')': /session/70cfe529f8eaa96315933f26d430f1a0
[2025-04-14T15:24:16.650+0000] {taskinstance.py:341} INFO - ::group::Post task execution logs
[2025-04-14T15:24:16.664+0000] {process_utils.py:80} INFO - Process psutil.Process(pid=1183, status='terminated', exitcode=0, started='15:24:05') (1183) terminated with exit code 0
[2025-04-14T15:24:16.665+0000] {process_utils.py:80} INFO - Process psutil.Process(pid=1563, status='terminated', started='15:24:11') (1563) terminated with exit code None
[2025-04-14T15:24:16.666+0000] {process_utils.py:80} INFO - Process psutil.Process(pid=1672, status='terminated', started='15:24:13') (1672) terminated with exit code None
[2025-04-14T15:24:16.667+0000] {process_utils.py:80} INFO - Process psutil.Process(pid=1629, status='terminated', started='15:24:12') (1629) terminated with exit code None
[2025-04-14T15:24:16.667+0000] {process_utils.py:80} INFO - Process psutil.Process(pid=1619, status='terminated', started='15:24:12') (1619) terminated with exit code None
[2025-04-14T15:24:16.668+0000] {process_utils.py:80} INFO - Process psutil.Process(pid=1579, status='terminated', started='15:24:11') (1579) terminated with exit code None
[2025-04-14T15:24:16.669+0000] {process_utils.py:80} INFO - Process psutil.Process(pid=1520, status='terminated', started='15:24:11') (1520) terminated with exit code None
[2025-04-14T15:24:16.670+0000] {process_utils.py:80} INFO - Process psutil.Process(pid=1506, status='terminated', started='15:24:11') (1506) terminated with exit code None
